[2025-03-15T02:34:18.208+0000] {local_task_job_runner.py:123} INFO - ::group::Pre task execution logs
[2025-03-15T02:34:18.214+0000] {taskinstance.py:2614} INFO - Dependencies all met for dep_context=non-requeueable deps ti=<TaskInstance: training-pipeline.training manual__2025-03-15T02:34:11.111705+00:00 [queued]>
[2025-03-15T02:34:18.216+0000] {taskinstance.py:2614} INFO - Dependencies all met for dep_context=requeueable deps ti=<TaskInstance: training-pipeline.training manual__2025-03-15T02:34:11.111705+00:00 [queued]>
[2025-03-15T02:34:18.216+0000] {taskinstance.py:2867} INFO - Starting attempt 1 of 1
[2025-03-15T02:34:18.220+0000] {taskinstance.py:2890} INFO - Executing <Task(PythonOperator): training> on 2025-03-15 02:34:11.111705+00:00
[2025-03-15T02:34:18.224+0000] {warnings.py:112} WARNING - /home/***/.local/lib/python3.12/site-packages/***/task/task_runner/standard_task_runner.py:70: DeprecationWarning: This process (pid=69) is multi-threaded, use of fork() may lead to deadlocks in the child.
  pid = os.fork()

[2025-03-15T02:34:18.224+0000] {standard_task_runner.py:72} INFO - Started process 79 to run task
[2025-03-15T02:34:18.224+0000] {standard_task_runner.py:104} INFO - Running: ['***', 'tasks', 'run', 'training-pipeline', 'training', 'manual__2025-03-15T02:34:11.111705+00:00', '--job-id', '38', '--raw', '--subdir', 'DAGS_FOLDER/training_pipeline.py', '--cfg-path', '/tmp/tmp62uw9w5w']
[2025-03-15T02:34:18.225+0000] {standard_task_runner.py:105} INFO - Job 38: Subtask training
[2025-03-15T02:34:18.239+0000] {task_command.py:467} INFO - Running <TaskInstance: training-pipeline.training manual__2025-03-15T02:34:11.111705+00:00 [running]> on host 7397b1e763f4
[2025-03-15T02:34:18.259+0000] {taskinstance.py:3134} INFO - Exporting env vars: AIRFLOW_CTX_DAG_OWNER='user' AIRFLOW_CTX_DAG_ID='training-pipeline' AIRFLOW_CTX_TASK_ID='training' AIRFLOW_CTX_EXECUTION_DATE='2025-03-15T02:34:11.111705+00:00' AIRFLOW_CTX_TRY_NUMBER='1' AIRFLOW_CTX_DAG_RUN_ID='manual__2025-03-15T02:34:11.111705+00:00'
[2025-03-15T02:34:18.260+0000] {taskinstance.py:732} INFO - ::endgroup::
[2025-03-15T02:34:18.743+0000] {logging_mixin.py:190} INFO -       Iter       Train Loss   Remaining Time 
[2025-03-15T02:34:18.766+0000] {logging_mixin.py:190} INFO -          1           1.2555            2.23s
[2025-03-15T02:34:18.787+0000] {logging_mixin.py:190} INFO -          2           1.1994            2.13s
[2025-03-15T02:34:18.808+0000] {logging_mixin.py:190} INFO -          3           1.1514            2.07s
[2025-03-15T02:34:18.828+0000] {logging_mixin.py:190} INFO -          4           1.1108            2.04s
[2025-03-15T02:34:18.849+0000] {logging_mixin.py:190} INFO -          5           1.0757            2.00s
[2025-03-15T02:34:18.870+0000] {logging_mixin.py:190} INFO -          6           1.0459            1.98s
[2025-03-15T02:34:18.891+0000] {logging_mixin.py:190} INFO -          7           1.0205            1.96s
[2025-03-15T02:34:18.911+0000] {logging_mixin.py:190} INFO -          8           0.9967            1.93s
[2025-03-15T02:34:18.932+0000] {logging_mixin.py:190} INFO -          9           0.9756            1.91s
[2025-03-15T02:34:18.953+0000] {logging_mixin.py:190} INFO -         10           0.9574            1.89s
[2025-03-15T02:34:19.164+0000] {logging_mixin.py:190} INFO -         20           0.8336            1.68s
[2025-03-15T02:34:19.372+0000] {logging_mixin.py:190} INFO -         30           0.7670            1.47s
[2025-03-15T02:34:19.584+0000] {logging_mixin.py:190} INFO -         40           0.7257            1.26s
[2025-03-15T02:34:19.791+0000] {logging_mixin.py:190} INFO -         50           0.6982            1.05s
[2025-03-15T02:34:19.998+0000] {logging_mixin.py:190} INFO -         60           0.6781            0.84s
[2025-03-15T02:34:20.205+0000] {logging_mixin.py:190} INFO -         70           0.6628            0.63s
[2025-03-15T02:34:20.426+0000] {logging_mixin.py:190} INFO -         80           0.6512            0.42s
[2025-03-15T02:34:20.667+0000] {logging_mixin.py:190} INFO -         90           0.6412            0.21s
[2025-03-15T02:34:20.877+0000] {logging_mixin.py:190} INFO -        100           0.6339            0.00s
[2025-03-15T02:34:20.988+0000] {logging_mixin.py:190} INFO -               precision    recall  f1-score   support

           0       0.87      0.90      0.88     60259
           1       0.82      0.77      0.79     35253

    accuracy                           0.85     95512
   macro avg       0.84      0.83      0.84     95512
weighted avg       0.85      0.85      0.85     95512
[2025-03-15T02:34:23.687+0000] {logging_mixin.py:190} WARNING - 2025/03/15 02:34:23 WARNING mlflow.models.model: Model logged without a signature and input example. Please set `input_example` parameter when logging the model to auto infer the model signature.
[2025-03-15T02:34:23.886+0000] {credentials.py:1147} INFO - Found credentials in environment variables.
[2025-03-15T02:34:23.923+0000] {logging_mixin.py:190} INFO - üèÉ View run dapper-ox-263 at: http://mlflow-server:5500/#/experiments/1/runs/b2481eb0b881433985ec0b893a6375bc
[2025-03-15T02:34:23.923+0000] {logging_mixin.py:190} INFO - üß™ View experiment at: http://mlflow-server:5500/#/experiments/1
[2025-03-15T02:34:23.928+0000] {taskinstance.py:3313} ERROR - Task failed with exception
Traceback (most recent call last):
  File "/home/airflow/.local/lib/python3.12/site-packages/boto3/s3/transfer.py", line 372, in upload_file
    future.result()
  File "/home/airflow/.local/lib/python3.12/site-packages/s3transfer/futures.py", line 103, in result
    return self._coordinator.result()
           ^^^^^^^^^^^^^^^^^^^^^^^^^^
  File "/home/airflow/.local/lib/python3.12/site-packages/s3transfer/futures.py", line 264, in result
    raise self._exception
  File "/home/airflow/.local/lib/python3.12/site-packages/s3transfer/tasks.py", line 135, in __call__
    return self._execute_main(kwargs)
           ^^^^^^^^^^^^^^^^^^^^^^^^^^
  File "/home/airflow/.local/lib/python3.12/site-packages/s3transfer/tasks.py", line 158, in _execute_main
    return_value = self._main(**kwargs)
                   ^^^^^^^^^^^^^^^^^^^^
  File "/home/airflow/.local/lib/python3.12/site-packages/s3transfer/upload.py", line 796, in _main
    client.put_object(Bucket=bucket, Key=key, Body=body, **extra_args)
  File "/home/airflow/.local/lib/python3.12/site-packages/botocore/client.py", line 569, in _api_call
    return self._make_api_call(operation_name, kwargs)
           ^^^^^^^^^^^^^^^^^^^^^^^^^^^^^^^^^^^^^^^^^^^
  File "/home/airflow/.local/lib/python3.12/site-packages/botocore/client.py", line 1023, in _make_api_call
    raise error_class(parsed_response, operation_name)
botocore.exceptions.ClientError: An error occurred (XMinioInvalidObjectName) when calling the PutObject operation: Object name contains unsupported characters.

During handling of the above exception, another exception occurred:

Traceback (most recent call last):
  File "/home/airflow/.local/lib/python3.12/site-packages/airflow/models/taskinstance.py", line 768, in _execute_task
    result = _execute_callable(context=context, **execute_callable_kwargs)
             ^^^^^^^^^^^^^^^^^^^^^^^^^^^^^^^^^^^^^^^^^^^^^^^^^^^^^^^^^^^^^
  File "/home/airflow/.local/lib/python3.12/site-packages/airflow/models/taskinstance.py", line 734, in _execute_callable
    return ExecutionCallableRunner(
           ^^^^^^^^^^^^^^^^^^^^^^^^
  File "/home/airflow/.local/lib/python3.12/site-packages/airflow/utils/operator_helpers.py", line 252, in run
    return self.func(*args, **kwargs)
           ^^^^^^^^^^^^^^^^^^^^^^^^^^
  File "/home/airflow/.local/lib/python3.12/site-packages/airflow/models/baseoperator.py", line 424, in wrapper
    return func(self, *args, **kwargs)
           ^^^^^^^^^^^^^^^^^^^^^^^^^^^
  File "/home/airflow/.local/lib/python3.12/site-packages/airflow/operators/python.py", line 238, in execute
    return_value = self.execute_callable()
                   ^^^^^^^^^^^^^^^^^^^^^^^
  File "/home/airflow/.local/lib/python3.12/site-packages/airflow/operators/python.py", line 256, in execute_callable
    return runner.run(*self.op_args, **self.op_kwargs)
           ^^^^^^^^^^^^^^^^^^^^^^^^^^^^^^^^^^^^^^^^^^^
  File "/home/airflow/.local/lib/python3.12/site-packages/airflow/utils/operator_helpers.py", line 252, in run
    return self.func(*args, **kwargs)
           ^^^^^^^^^^^^^^^^^^^^^^^^^^
  File "/opt/airflow/dags/steps/train_step.py", line 103, in __call__
    mlflow.sklearn.log_model(
  File "/home/airflow/.local/lib/python3.12/site-packages/mlflow/sklearn/__init__.py", line 413, in log_model
    return Model.log(
           ^^^^^^^^^^
  File "/home/airflow/.local/lib/python3.12/site-packages/mlflow/models/model.py", line 932, in log
    mlflow.tracking.fluent.log_artifacts(local_path, mlflow_model.artifact_path, run_id)
  File "/home/airflow/.local/lib/python3.12/site-packages/mlflow/tracking/fluent.py", line 1219, in log_artifacts
    MlflowClient().log_artifacts(run_id, local_dir, artifact_path)
  File "/home/airflow/.local/lib/python3.12/site-packages/mlflow/tracking/client.py", line 2426, in log_artifacts
    self._tracking_client.log_artifacts(run_id, local_dir, artifact_path)
  File "/home/airflow/.local/lib/python3.12/site-packages/mlflow/tracking/_tracking_service/client.py", line 959, in log_artifacts
    self._get_artifact_repo(run_id).log_artifacts(local_dir, artifact_path)
  File "/home/airflow/.local/lib/python3.12/site-packages/mlflow/store/artifact/s3_artifact_repo.py", line 194, in log_artifacts
    self._upload_file(
  File "/home/airflow/.local/lib/python3.12/site-packages/mlflow/store/artifact/s3_artifact_repo.py", line 169, in _upload_file
    s3_client.upload_file(Filename=local_file, Bucket=bucket, Key=key, ExtraArgs=extra_args)
  File "/home/airflow/.local/lib/python3.12/site-packages/boto3/s3/inject.py", line 145, in upload_file
    return transfer.upload_file(
           ^^^^^^^^^^^^^^^^^^^^^
  File "/home/airflow/.local/lib/python3.12/site-packages/boto3/s3/transfer.py", line 378, in upload_file
    raise S3UploadFailedError(
boto3.exceptions.S3UploadFailedError: Failed to upload /tmp/tmpmc7ohgpf/model/requirements.txt to mlflow/1/b2481eb0b881433985ec0b893a6375bc/artifacts/s3://mlflow/cancellation_estimator/requirements.txt: An error occurred (XMinioInvalidObjectName) when calling the PutObject operation: Object name contains unsupported characters.
[2025-03-15T02:34:23.938+0000] {taskinstance.py:1226} INFO - Marking task as FAILED. dag_id=training-pipeline, task_id=training, run_id=manual__2025-03-15T02:34:11.111705+00:00, execution_date=20250315T023411, start_date=20250315T023418, end_date=20250315T023423
[2025-03-15T02:34:23.946+0000] {taskinstance.py:341} INFO - ::group::Post task execution logs
[2025-03-15T02:34:23.946+0000] {standard_task_runner.py:124} ERROR - Failed to execute job 38 for task training (Failed to upload /tmp/tmpmc7ohgpf/model/requirements.txt to mlflow/1/b2481eb0b881433985ec0b893a6375bc/artifacts/s3://mlflow/cancellation_estimator/requirements.txt: An error occurred (XMinioInvalidObjectName) when calling the PutObject operation: Object name contains unsupported characters.; 79)
Traceback (most recent call last):
  File "/home/airflow/.local/lib/python3.12/site-packages/boto3/s3/transfer.py", line 372, in upload_file
    future.result()
  File "/home/airflow/.local/lib/python3.12/site-packages/s3transfer/futures.py", line 103, in result
    return self._coordinator.result()
           ^^^^^^^^^^^^^^^^^^^^^^^^^^
  File "/home/airflow/.local/lib/python3.12/site-packages/s3transfer/futures.py", line 264, in result
    raise self._exception
  File "/home/airflow/.local/lib/python3.12/site-packages/s3transfer/tasks.py", line 135, in __call__
    return self._execute_main(kwargs)
           ^^^^^^^^^^^^^^^^^^^^^^^^^^
  File "/home/airflow/.local/lib/python3.12/site-packages/s3transfer/tasks.py", line 158, in _execute_main
    return_value = self._main(**kwargs)
                   ^^^^^^^^^^^^^^^^^^^^
  File "/home/airflow/.local/lib/python3.12/site-packages/s3transfer/upload.py", line 796, in _main
    client.put_object(Bucket=bucket, Key=key, Body=body, **extra_args)
  File "/home/airflow/.local/lib/python3.12/site-packages/botocore/client.py", line 569, in _api_call
    return self._make_api_call(operation_name, kwargs)
           ^^^^^^^^^^^^^^^^^^^^^^^^^^^^^^^^^^^^^^^^^^^
  File "/home/airflow/.local/lib/python3.12/site-packages/botocore/client.py", line 1023, in _make_api_call
    raise error_class(parsed_response, operation_name)
botocore.exceptions.ClientError: An error occurred (XMinioInvalidObjectName) when calling the PutObject operation: Object name contains unsupported characters.

During handling of the above exception, another exception occurred:

Traceback (most recent call last):
  File "/home/airflow/.local/lib/python3.12/site-packages/airflow/task/task_runner/standard_task_runner.py", line 117, in _start_by_fork
    ret = args.func(args, dag=self.dag)
          ^^^^^^^^^^^^^^^^^^^^^^^^^^^^^
  File "/home/airflow/.local/lib/python3.12/site-packages/airflow/cli/cli_config.py", line 49, in command
    return func(*args, **kwargs)
           ^^^^^^^^^^^^^^^^^^^^^
  File "/home/airflow/.local/lib/python3.12/site-packages/airflow/utils/cli.py", line 116, in wrapper
    return f(*args, **kwargs)
           ^^^^^^^^^^^^^^^^^^
  File "/home/airflow/.local/lib/python3.12/site-packages/airflow/cli/commands/task_command.py", line 483, in task_run
    task_return_code = _run_task_by_selected_method(args, _dag, ti)
                       ^^^^^^^^^^^^^^^^^^^^^^^^^^^^^^^^^^^^^^^^^^^^
  File "/home/airflow/.local/lib/python3.12/site-packages/airflow/cli/commands/task_command.py", line 256, in _run_task_by_selected_method
    return _run_raw_task(args, ti)
           ^^^^^^^^^^^^^^^^^^^^^^^
  File "/home/airflow/.local/lib/python3.12/site-packages/airflow/cli/commands/task_command.py", line 341, in _run_raw_task
    return ti._run_raw_task(
           ^^^^^^^^^^^^^^^^^
  File "/home/airflow/.local/lib/python3.12/site-packages/airflow/utils/session.py", line 97, in wrapper
    return func(*args, session=session, **kwargs)
           ^^^^^^^^^^^^^^^^^^^^^^^^^^^^^^^^^^^^^^
  File "/home/airflow/.local/lib/python3.12/site-packages/airflow/models/taskinstance.py", line 3006, in _run_raw_task
    return _run_raw_task(
           ^^^^^^^^^^^^^^
  File "/home/airflow/.local/lib/python3.12/site-packages/airflow/models/taskinstance.py", line 274, in _run_raw_task
    TaskInstance._execute_task_with_callbacks(
  File "/home/airflow/.local/lib/python3.12/site-packages/airflow/models/taskinstance.py", line 3161, in _execute_task_with_callbacks
    result = self._execute_task(context, task_orig)
             ^^^^^^^^^^^^^^^^^^^^^^^^^^^^^^^^^^^^^^
  File "/home/airflow/.local/lib/python3.12/site-packages/airflow/models/taskinstance.py", line 3185, in _execute_task
    return _execute_task(self, context, task_orig)
           ^^^^^^^^^^^^^^^^^^^^^^^^^^^^^^^^^^^^^^^
  File "/home/airflow/.local/lib/python3.12/site-packages/airflow/models/taskinstance.py", line 768, in _execute_task
    result = _execute_callable(context=context, **execute_callable_kwargs)
             ^^^^^^^^^^^^^^^^^^^^^^^^^^^^^^^^^^^^^^^^^^^^^^^^^^^^^^^^^^^^^
  File "/home/airflow/.local/lib/python3.12/site-packages/airflow/models/taskinstance.py", line 734, in _execute_callable
    return ExecutionCallableRunner(
           ^^^^^^^^^^^^^^^^^^^^^^^^
  File "/home/airflow/.local/lib/python3.12/site-packages/airflow/utils/operator_helpers.py", line 252, in run
    return self.func(*args, **kwargs)
           ^^^^^^^^^^^^^^^^^^^^^^^^^^
  File "/home/airflow/.local/lib/python3.12/site-packages/airflow/models/baseoperator.py", line 424, in wrapper
    return func(self, *args, **kwargs)
           ^^^^^^^^^^^^^^^^^^^^^^^^^^^
  File "/home/airflow/.local/lib/python3.12/site-packages/airflow/operators/python.py", line 238, in execute
    return_value = self.execute_callable()
                   ^^^^^^^^^^^^^^^^^^^^^^^
  File "/home/airflow/.local/lib/python3.12/site-packages/airflow/operators/python.py", line 256, in execute_callable
    return runner.run(*self.op_args, **self.op_kwargs)
           ^^^^^^^^^^^^^^^^^^^^^^^^^^^^^^^^^^^^^^^^^^^
  File "/home/airflow/.local/lib/python3.12/site-packages/airflow/utils/operator_helpers.py", line 252, in run
    return self.func(*args, **kwargs)
           ^^^^^^^^^^^^^^^^^^^^^^^^^^
  File "/opt/airflow/dags/steps/train_step.py", line 103, in __call__
    mlflow.sklearn.log_model(
  File "/home/airflow/.local/lib/python3.12/site-packages/mlflow/sklearn/__init__.py", line 413, in log_model
    return Model.log(
           ^^^^^^^^^^
  File "/home/airflow/.local/lib/python3.12/site-packages/mlflow/models/model.py", line 932, in log
    mlflow.tracking.fluent.log_artifacts(local_path, mlflow_model.artifact_path, run_id)
  File "/home/airflow/.local/lib/python3.12/site-packages/mlflow/tracking/fluent.py", line 1219, in log_artifacts
    MlflowClient().log_artifacts(run_id, local_dir, artifact_path)
  File "/home/airflow/.local/lib/python3.12/site-packages/mlflow/tracking/client.py", line 2426, in log_artifacts
    self._tracking_client.log_artifacts(run_id, local_dir, artifact_path)
  File "/home/airflow/.local/lib/python3.12/site-packages/mlflow/tracking/_tracking_service/client.py", line 959, in log_artifacts
    self._get_artifact_repo(run_id).log_artifacts(local_dir, artifact_path)
  File "/home/airflow/.local/lib/python3.12/site-packages/mlflow/store/artifact/s3_artifact_repo.py", line 194, in log_artifacts
    self._upload_file(
  File "/home/airflow/.local/lib/python3.12/site-packages/mlflow/store/artifact/s3_artifact_repo.py", line 169, in _upload_file
    s3_client.upload_file(Filename=local_file, Bucket=bucket, Key=key, ExtraArgs=extra_args)
  File "/home/airflow/.local/lib/python3.12/site-packages/boto3/s3/inject.py", line 145, in upload_file
    return transfer.upload_file(
           ^^^^^^^^^^^^^^^^^^^^^
  File "/home/airflow/.local/lib/python3.12/site-packages/boto3/s3/transfer.py", line 378, in upload_file
    raise S3UploadFailedError(
boto3.exceptions.S3UploadFailedError: Failed to upload /tmp/tmpmc7ohgpf/model/requirements.txt to mlflow/1/b2481eb0b881433985ec0b893a6375bc/artifacts/s3://mlflow/cancellation_estimator/requirements.txt: An error occurred (XMinioInvalidObjectName) when calling the PutObject operation: Object name contains unsupported characters.
[2025-03-15T02:34:23.968+0000] {local_task_job_runner.py:266} INFO - Task exited with return code 1
[2025-03-15T02:34:23.975+0000] {taskinstance.py:3901} INFO - 0 downstream tasks scheduled from follow-on schedule check
[2025-03-15T02:34:23.976+0000] {local_task_job_runner.py:245} INFO - ::endgroup::
