[2025-03-15T02:35:19.711+0000] {local_task_job_runner.py:123} INFO - ::group::Pre task execution logs
[2025-03-15T02:35:19.717+0000] {taskinstance.py:2614} INFO - Dependencies all met for dep_context=non-requeueable deps ti=<TaskInstance: training-pipeline.training manual__2025-03-15T02:35:13.845334+00:00 [queued]>
[2025-03-15T02:35:19.720+0000] {taskinstance.py:2614} INFO - Dependencies all met for dep_context=requeueable deps ti=<TaskInstance: training-pipeline.training manual__2025-03-15T02:35:13.845334+00:00 [queued]>
[2025-03-15T02:35:19.720+0000] {taskinstance.py:2867} INFO - Starting attempt 1 of 1
[2025-03-15T02:35:19.801+0000] {taskinstance.py:2890} INFO - Executing <Task(PythonOperator): training> on 2025-03-15 02:35:13.845334+00:00
[2025-03-15T02:35:19.805+0000] {warnings.py:112} WARNING - /home/***/.local/lib/python3.12/site-packages/***/task/task_runner/standard_task_runner.py:70: DeprecationWarning: This process (pid=194) is multi-threaded, use of fork() may lead to deadlocks in the child.
  pid = os.fork()

[2025-03-15T02:35:19.805+0000] {standard_task_runner.py:72} INFO - Started process 204 to run task
[2025-03-15T02:35:19.806+0000] {standard_task_runner.py:104} INFO - Running: ['***', 'tasks', 'run', 'training-pipeline', 'training', 'manual__2025-03-15T02:35:13.845334+00:00', '--job-id', '41', '--raw', '--subdir', 'DAGS_FOLDER/training_pipeline.py', '--cfg-path', '/tmp/tmpt8q6y9nk']
[2025-03-15T02:35:19.806+0000] {standard_task_runner.py:105} INFO - Job 41: Subtask training
[2025-03-15T02:35:19.822+0000] {task_command.py:467} INFO - Running <TaskInstance: training-pipeline.training manual__2025-03-15T02:35:13.845334+00:00 [running]> on host 6cb8bcf5e778
[2025-03-15T02:35:19.855+0000] {taskinstance.py:3134} INFO - Exporting env vars: AIRFLOW_CTX_DAG_OWNER='user' AIRFLOW_CTX_DAG_ID='training-pipeline' AIRFLOW_CTX_TASK_ID='training' AIRFLOW_CTX_EXECUTION_DATE='2025-03-15T02:35:13.845334+00:00' AIRFLOW_CTX_TRY_NUMBER='1' AIRFLOW_CTX_DAG_RUN_ID='manual__2025-03-15T02:35:13.845334+00:00'
[2025-03-15T02:35:19.856+0000] {taskinstance.py:732} INFO - ::endgroup::
[2025-03-15T02:35:20.178+0000] {logging_mixin.py:190} INFO -       Iter       Train Loss   Remaining Time 
[2025-03-15T02:35:20.200+0000] {logging_mixin.py:190} INFO -          1           1.2558            2.12s
[2025-03-15T02:35:20.221+0000] {logging_mixin.py:190} INFO -          2           1.1997            2.08s
[2025-03-15T02:35:20.242+0000] {logging_mixin.py:190} INFO -          3           1.1516            2.03s
[2025-03-15T02:35:20.262+0000] {logging_mixin.py:190} INFO -          4           1.1111            2.01s
[2025-03-15T02:35:20.283+0000] {logging_mixin.py:190} INFO -          5           1.0773            1.99s
[2025-03-15T02:35:20.304+0000] {logging_mixin.py:190} INFO -          6           1.0460            1.96s
[2025-03-15T02:35:20.325+0000] {logging_mixin.py:190} INFO -          7           1.0210            1.94s
[2025-03-15T02:35:20.345+0000] {logging_mixin.py:190} INFO -          8           0.9969            1.91s
[2025-03-15T02:35:20.366+0000] {logging_mixin.py:190} INFO -          9           0.9758            1.89s
[2025-03-15T02:35:20.386+0000] {logging_mixin.py:190} INFO -         10           0.9577            1.87s
[2025-03-15T02:35:20.616+0000] {logging_mixin.py:190} INFO -         20           0.8269            1.75s
[2025-03-15T02:35:20.821+0000] {logging_mixin.py:190} INFO -         30           0.7632            1.50s
[2025-03-15T02:35:21.033+0000] {logging_mixin.py:190} INFO -         40           0.7212            1.28s
[2025-03-15T02:35:21.238+0000] {logging_mixin.py:190} INFO -         50           0.6956            1.06s
[2025-03-15T02:35:21.444+0000] {logging_mixin.py:190} INFO -         60           0.6746            0.84s
[2025-03-15T02:35:21.648+0000] {logging_mixin.py:190} INFO -         70           0.6605            0.63s
[2025-03-15T02:35:21.855+0000] {logging_mixin.py:190} INFO -         80           0.6498            0.42s
[2025-03-15T02:35:22.062+0000] {logging_mixin.py:190} INFO -         90           0.6413            0.21s
[2025-03-15T02:35:22.270+0000] {logging_mixin.py:190} INFO -        100           0.6335            0.00s
[2025-03-15T02:35:22.409+0000] {logging_mixin.py:190} INFO -               precision    recall  f1-score   support

           0       0.87      0.90      0.88     60259
           1       0.82      0.77      0.79     35253

    accuracy                           0.85     95512
   macro avg       0.84      0.83      0.84     95512
weighted avg       0.85      0.85      0.85     95512
[2025-03-15T02:35:24.670+0000] {logging_mixin.py:190} WARNING - 2025/03/15 02:35:24 WARNING mlflow.models.model: Model logged without a signature and input example. Please set `input_example` parameter when logging the model to auto infer the model signature.
[2025-03-15T02:35:24.690+0000] {credentials.py:1147} INFO - Found credentials in environment variables.
[2025-03-15T02:35:24.712+0000] {logging_mixin.py:190} INFO - üèÉ View run melodic-sponge-218 at: http://mlflow-server:5500/#/experiments/1/runs/fc1f85de4c3745c4a10ea79d8568a5be
[2025-03-15T02:35:24.712+0000] {logging_mixin.py:190} INFO - üß™ View experiment at: http://mlflow-server:5500/#/experiments/1
[2025-03-15T02:35:24.732+0000] {taskinstance.py:3313} ERROR - Task failed with exception
Traceback (most recent call last):
  File "/home/airflow/.local/lib/python3.12/site-packages/boto3/s3/transfer.py", line 372, in upload_file
    future.result()
  File "/home/airflow/.local/lib/python3.12/site-packages/s3transfer/futures.py", line 103, in result
    return self._coordinator.result()
           ^^^^^^^^^^^^^^^^^^^^^^^^^^
  File "/home/airflow/.local/lib/python3.12/site-packages/s3transfer/futures.py", line 264, in result
    raise self._exception
  File "/home/airflow/.local/lib/python3.12/site-packages/s3transfer/tasks.py", line 135, in __call__
    return self._execute_main(kwargs)
           ^^^^^^^^^^^^^^^^^^^^^^^^^^
  File "/home/airflow/.local/lib/python3.12/site-packages/s3transfer/tasks.py", line 158, in _execute_main
    return_value = self._main(**kwargs)
                   ^^^^^^^^^^^^^^^^^^^^
  File "/home/airflow/.local/lib/python3.12/site-packages/s3transfer/upload.py", line 796, in _main
    client.put_object(Bucket=bucket, Key=key, Body=body, **extra_args)
  File "/home/airflow/.local/lib/python3.12/site-packages/botocore/client.py", line 569, in _api_call
    return self._make_api_call(operation_name, kwargs)
           ^^^^^^^^^^^^^^^^^^^^^^^^^^^^^^^^^^^^^^^^^^^
  File "/home/airflow/.local/lib/python3.12/site-packages/botocore/client.py", line 1023, in _make_api_call
    raise error_class(parsed_response, operation_name)
botocore.exceptions.ClientError: An error occurred (XMinioInvalidObjectName) when calling the PutObject operation: Object name contains unsupported characters.

During handling of the above exception, another exception occurred:

Traceback (most recent call last):
  File "/home/airflow/.local/lib/python3.12/site-packages/airflow/models/taskinstance.py", line 768, in _execute_task
    result = _execute_callable(context=context, **execute_callable_kwargs)
             ^^^^^^^^^^^^^^^^^^^^^^^^^^^^^^^^^^^^^^^^^^^^^^^^^^^^^^^^^^^^^
  File "/home/airflow/.local/lib/python3.12/site-packages/airflow/models/taskinstance.py", line 734, in _execute_callable
    return ExecutionCallableRunner(
           ^^^^^^^^^^^^^^^^^^^^^^^^
  File "/home/airflow/.local/lib/python3.12/site-packages/airflow/utils/operator_helpers.py", line 252, in run
    return self.func(*args, **kwargs)
           ^^^^^^^^^^^^^^^^^^^^^^^^^^
  File "/home/airflow/.local/lib/python3.12/site-packages/airflow/models/baseoperator.py", line 424, in wrapper
    return func(self, *args, **kwargs)
           ^^^^^^^^^^^^^^^^^^^^^^^^^^^
  File "/home/airflow/.local/lib/python3.12/site-packages/airflow/operators/python.py", line 238, in execute
    return_value = self.execute_callable()
                   ^^^^^^^^^^^^^^^^^^^^^^^
  File "/home/airflow/.local/lib/python3.12/site-packages/airflow/operators/python.py", line 256, in execute_callable
    return runner.run(*self.op_args, **self.op_kwargs)
           ^^^^^^^^^^^^^^^^^^^^^^^^^^^^^^^^^^^^^^^^^^^
  File "/home/airflow/.local/lib/python3.12/site-packages/airflow/utils/operator_helpers.py", line 252, in run
    return self.func(*args, **kwargs)
           ^^^^^^^^^^^^^^^^^^^^^^^^^^
  File "/opt/airflow/dags/steps/train_step.py", line 103, in __call__
    mlflow.sklearn.log_model(
  File "/home/airflow/.local/lib/python3.12/site-packages/mlflow/sklearn/__init__.py", line 413, in log_model
    return Model.log(
           ^^^^^^^^^^
  File "/home/airflow/.local/lib/python3.12/site-packages/mlflow/models/model.py", line 932, in log
    mlflow.tracking.fluent.log_artifacts(local_path, mlflow_model.artifact_path, run_id)
  File "/home/airflow/.local/lib/python3.12/site-packages/mlflow/tracking/fluent.py", line 1219, in log_artifacts
    MlflowClient().log_artifacts(run_id, local_dir, artifact_path)
  File "/home/airflow/.local/lib/python3.12/site-packages/mlflow/tracking/client.py", line 2426, in log_artifacts
    self._tracking_client.log_artifacts(run_id, local_dir, artifact_path)
  File "/home/airflow/.local/lib/python3.12/site-packages/mlflow/tracking/_tracking_service/client.py", line 959, in log_artifacts
    self._get_artifact_repo(run_id).log_artifacts(local_dir, artifact_path)
  File "/home/airflow/.local/lib/python3.12/site-packages/mlflow/store/artifact/s3_artifact_repo.py", line 194, in log_artifacts
    self._upload_file(
  File "/home/airflow/.local/lib/python3.12/site-packages/mlflow/store/artifact/s3_artifact_repo.py", line 169, in _upload_file
    s3_client.upload_file(Filename=local_file, Bucket=bucket, Key=key, ExtraArgs=extra_args)
  File "/home/airflow/.local/lib/python3.12/site-packages/boto3/s3/inject.py", line 145, in upload_file
    return transfer.upload_file(
           ^^^^^^^^^^^^^^^^^^^^^
  File "/home/airflow/.local/lib/python3.12/site-packages/boto3/s3/transfer.py", line 378, in upload_file
    raise S3UploadFailedError(
boto3.exceptions.S3UploadFailedError: Failed to upload /tmp/tmpbxeuvaxw/model/requirements.txt to mlflow/1/fc1f85de4c3745c4a10ea79d8568a5be/artifacts/s3://mlflow/cancellation_estimator/requirements.txt: An error occurred (XMinioInvalidObjectName) when calling the PutObject operation: Object name contains unsupported characters.
[2025-03-15T02:35:24.746+0000] {taskinstance.py:1226} INFO - Marking task as FAILED. dag_id=training-pipeline, task_id=training, run_id=manual__2025-03-15T02:35:13.845334+00:00, execution_date=20250315T023513, start_date=20250315T023519, end_date=20250315T023524
[2025-03-15T02:35:24.755+0000] {taskinstance.py:341} INFO - ::group::Post task execution logs
[2025-03-15T02:35:24.755+0000] {standard_task_runner.py:124} ERROR - Failed to execute job 41 for task training (Failed to upload /tmp/tmpbxeuvaxw/model/requirements.txt to mlflow/1/fc1f85de4c3745c4a10ea79d8568a5be/artifacts/s3://mlflow/cancellation_estimator/requirements.txt: An error occurred (XMinioInvalidObjectName) when calling the PutObject operation: Object name contains unsupported characters.; 204)
Traceback (most recent call last):
  File "/home/airflow/.local/lib/python3.12/site-packages/boto3/s3/transfer.py", line 372, in upload_file
    future.result()
  File "/home/airflow/.local/lib/python3.12/site-packages/s3transfer/futures.py", line 103, in result
    return self._coordinator.result()
           ^^^^^^^^^^^^^^^^^^^^^^^^^^
  File "/home/airflow/.local/lib/python3.12/site-packages/s3transfer/futures.py", line 264, in result
    raise self._exception
  File "/home/airflow/.local/lib/python3.12/site-packages/s3transfer/tasks.py", line 135, in __call__
    return self._execute_main(kwargs)
           ^^^^^^^^^^^^^^^^^^^^^^^^^^
  File "/home/airflow/.local/lib/python3.12/site-packages/s3transfer/tasks.py", line 158, in _execute_main
    return_value = self._main(**kwargs)
                   ^^^^^^^^^^^^^^^^^^^^
  File "/home/airflow/.local/lib/python3.12/site-packages/s3transfer/upload.py", line 796, in _main
    client.put_object(Bucket=bucket, Key=key, Body=body, **extra_args)
  File "/home/airflow/.local/lib/python3.12/site-packages/botocore/client.py", line 569, in _api_call
    return self._make_api_call(operation_name, kwargs)
           ^^^^^^^^^^^^^^^^^^^^^^^^^^^^^^^^^^^^^^^^^^^
  File "/home/airflow/.local/lib/python3.12/site-packages/botocore/client.py", line 1023, in _make_api_call
    raise error_class(parsed_response, operation_name)
botocore.exceptions.ClientError: An error occurred (XMinioInvalidObjectName) when calling the PutObject operation: Object name contains unsupported characters.

During handling of the above exception, another exception occurred:

Traceback (most recent call last):
  File "/home/airflow/.local/lib/python3.12/site-packages/airflow/task/task_runner/standard_task_runner.py", line 117, in _start_by_fork
    ret = args.func(args, dag=self.dag)
          ^^^^^^^^^^^^^^^^^^^^^^^^^^^^^
  File "/home/airflow/.local/lib/python3.12/site-packages/airflow/cli/cli_config.py", line 49, in command
    return func(*args, **kwargs)
           ^^^^^^^^^^^^^^^^^^^^^
  File "/home/airflow/.local/lib/python3.12/site-packages/airflow/utils/cli.py", line 116, in wrapper
    return f(*args, **kwargs)
           ^^^^^^^^^^^^^^^^^^
  File "/home/airflow/.local/lib/python3.12/site-packages/airflow/cli/commands/task_command.py", line 483, in task_run
    task_return_code = _run_task_by_selected_method(args, _dag, ti)
                       ^^^^^^^^^^^^^^^^^^^^^^^^^^^^^^^^^^^^^^^^^^^^
  File "/home/airflow/.local/lib/python3.12/site-packages/airflow/cli/commands/task_command.py", line 256, in _run_task_by_selected_method
    return _run_raw_task(args, ti)
           ^^^^^^^^^^^^^^^^^^^^^^^
  File "/home/airflow/.local/lib/python3.12/site-packages/airflow/cli/commands/task_command.py", line 341, in _run_raw_task
    return ti._run_raw_task(
           ^^^^^^^^^^^^^^^^^
  File "/home/airflow/.local/lib/python3.12/site-packages/airflow/utils/session.py", line 97, in wrapper
    return func(*args, session=session, **kwargs)
           ^^^^^^^^^^^^^^^^^^^^^^^^^^^^^^^^^^^^^^
  File "/home/airflow/.local/lib/python3.12/site-packages/airflow/models/taskinstance.py", line 3006, in _run_raw_task
    return _run_raw_task(
           ^^^^^^^^^^^^^^
  File "/home/airflow/.local/lib/python3.12/site-packages/airflow/models/taskinstance.py", line 274, in _run_raw_task
    TaskInstance._execute_task_with_callbacks(
  File "/home/airflow/.local/lib/python3.12/site-packages/airflow/models/taskinstance.py", line 3161, in _execute_task_with_callbacks
    result = self._execute_task(context, task_orig)
             ^^^^^^^^^^^^^^^^^^^^^^^^^^^^^^^^^^^^^^
  File "/home/airflow/.local/lib/python3.12/site-packages/airflow/models/taskinstance.py", line 3185, in _execute_task
    return _execute_task(self, context, task_orig)
           ^^^^^^^^^^^^^^^^^^^^^^^^^^^^^^^^^^^^^^^
  File "/home/airflow/.local/lib/python3.12/site-packages/airflow/models/taskinstance.py", line 768, in _execute_task
    result = _execute_callable(context=context, **execute_callable_kwargs)
             ^^^^^^^^^^^^^^^^^^^^^^^^^^^^^^^^^^^^^^^^^^^^^^^^^^^^^^^^^^^^^
  File "/home/airflow/.local/lib/python3.12/site-packages/airflow/models/taskinstance.py", line 734, in _execute_callable
    return ExecutionCallableRunner(
           ^^^^^^^^^^^^^^^^^^^^^^^^
  File "/home/airflow/.local/lib/python3.12/site-packages/airflow/utils/operator_helpers.py", line 252, in run
    return self.func(*args, **kwargs)
           ^^^^^^^^^^^^^^^^^^^^^^^^^^
  File "/home/airflow/.local/lib/python3.12/site-packages/airflow/models/baseoperator.py", line 424, in wrapper
    return func(self, *args, **kwargs)
           ^^^^^^^^^^^^^^^^^^^^^^^^^^^
  File "/home/airflow/.local/lib/python3.12/site-packages/airflow/operators/python.py", line 238, in execute
    return_value = self.execute_callable()
                   ^^^^^^^^^^^^^^^^^^^^^^^
  File "/home/airflow/.local/lib/python3.12/site-packages/airflow/operators/python.py", line 256, in execute_callable
    return runner.run(*self.op_args, **self.op_kwargs)
           ^^^^^^^^^^^^^^^^^^^^^^^^^^^^^^^^^^^^^^^^^^^
  File "/home/airflow/.local/lib/python3.12/site-packages/airflow/utils/operator_helpers.py", line 252, in run
    return self.func(*args, **kwargs)
           ^^^^^^^^^^^^^^^^^^^^^^^^^^
  File "/opt/airflow/dags/steps/train_step.py", line 103, in __call__
    mlflow.sklearn.log_model(
  File "/home/airflow/.local/lib/python3.12/site-packages/mlflow/sklearn/__init__.py", line 413, in log_model
    return Model.log(
           ^^^^^^^^^^
  File "/home/airflow/.local/lib/python3.12/site-packages/mlflow/models/model.py", line 932, in log
    mlflow.tracking.fluent.log_artifacts(local_path, mlflow_model.artifact_path, run_id)
  File "/home/airflow/.local/lib/python3.12/site-packages/mlflow/tracking/fluent.py", line 1219, in log_artifacts
    MlflowClient().log_artifacts(run_id, local_dir, artifact_path)
  File "/home/airflow/.local/lib/python3.12/site-packages/mlflow/tracking/client.py", line 2426, in log_artifacts
    self._tracking_client.log_artifacts(run_id, local_dir, artifact_path)
  File "/home/airflow/.local/lib/python3.12/site-packages/mlflow/tracking/_tracking_service/client.py", line 959, in log_artifacts
    self._get_artifact_repo(run_id).log_artifacts(local_dir, artifact_path)
  File "/home/airflow/.local/lib/python3.12/site-packages/mlflow/store/artifact/s3_artifact_repo.py", line 194, in log_artifacts
    self._upload_file(
  File "/home/airflow/.local/lib/python3.12/site-packages/mlflow/store/artifact/s3_artifact_repo.py", line 169, in _upload_file
    s3_client.upload_file(Filename=local_file, Bucket=bucket, Key=key, ExtraArgs=extra_args)
  File "/home/airflow/.local/lib/python3.12/site-packages/boto3/s3/inject.py", line 145, in upload_file
    return transfer.upload_file(
           ^^^^^^^^^^^^^^^^^^^^^
  File "/home/airflow/.local/lib/python3.12/site-packages/boto3/s3/transfer.py", line 378, in upload_file
    raise S3UploadFailedError(
boto3.exceptions.S3UploadFailedError: Failed to upload /tmp/tmpbxeuvaxw/model/requirements.txt to mlflow/1/fc1f85de4c3745c4a10ea79d8568a5be/artifacts/s3://mlflow/cancellation_estimator/requirements.txt: An error occurred (XMinioInvalidObjectName) when calling the PutObject operation: Object name contains unsupported characters.
[2025-03-15T02:35:24.784+0000] {local_task_job_runner.py:266} INFO - Task exited with return code 1
[2025-03-15T02:35:24.795+0000] {taskinstance.py:3901} INFO - 0 downstream tasks scheduled from follow-on schedule check
[2025-03-15T02:35:24.797+0000] {local_task_job_runner.py:245} INFO - ::endgroup::
