[2025-03-12T12:39:02.860+0000] {local_task_job_runner.py:123} INFO - ::group::Pre task execution logs
[2025-03-12T12:39:02.866+0000] {taskinstance.py:2614} INFO - Dependencies all met for dep_context=non-requeueable deps ti=<TaskInstance: training-pipeline.training manual__2025-03-12T12:38:57.214725+00:00 [queued]>
[2025-03-12T12:39:02.869+0000] {taskinstance.py:2614} INFO - Dependencies all met for dep_context=requeueable deps ti=<TaskInstance: training-pipeline.training manual__2025-03-12T12:38:57.214725+00:00 [queued]>
[2025-03-12T12:39:02.869+0000] {taskinstance.py:2867} INFO - Starting attempt 1 of 1
[2025-03-12T12:39:02.872+0000] {taskinstance.py:2890} INFO - Executing <Task(PythonOperator): training> on 2025-03-12 12:38:57.214725+00:00
[2025-03-12T12:39:02.878+0000] {warnings.py:112} WARNING - /home/***/.local/lib/python3.12/site-packages/***/task/task_runner/standard_task_runner.py:70: DeprecationWarning: This process (pid=273) is multi-threaded, use of fork() may lead to deadlocks in the child.
  pid = os.fork()

[2025-03-12T12:39:02.878+0000] {standard_task_runner.py:72} INFO - Started process 283 to run task
[2025-03-12T12:39:02.879+0000] {standard_task_runner.py:104} INFO - Running: ['***', 'tasks', 'run', 'training-pipeline', 'training', 'manual__2025-03-12T12:38:57.214725+00:00', '--job-id', '48', '--raw', '--subdir', 'DAGS_FOLDER/training_pipeline.py', '--cfg-path', '/tmp/tmpbx10re6x']
[2025-03-12T12:39:02.880+0000] {standard_task_runner.py:105} INFO - Job 48: Subtask training
[2025-03-12T12:39:02.896+0000] {task_command.py:467} INFO - Running <TaskInstance: training-pipeline.training manual__2025-03-12T12:38:57.214725+00:00 [running]> on host 40ef2732060a
[2025-03-12T12:39:02.918+0000] {taskinstance.py:3134} INFO - Exporting env vars: AIRFLOW_CTX_DAG_OWNER='user' AIRFLOW_CTX_DAG_ID='training-pipeline' AIRFLOW_CTX_TASK_ID='training' AIRFLOW_CTX_EXECUTION_DATE='2025-03-12T12:38:57.214725+00:00' AIRFLOW_CTX_TRY_NUMBER='1' AIRFLOW_CTX_DAG_RUN_ID='manual__2025-03-12T12:38:57.214725+00:00'
[2025-03-12T12:39:02.919+0000] {taskinstance.py:732} INFO - ::endgroup::
[2025-03-12T12:39:02.945+0000] {connectionpool.py:868} WARNING - Retrying (Retry(total=6, connect=6, read=7, redirect=7, status=7)) after connection broken by 'NewConnectionError('<urllib3.connection.HTTPConnection object at 0xffff8653a0f0>: Failed to establish a new connection: [Errno 111] Connection refused')': /api/2.0/mlflow/experiments/get-by-name?experiment_name=cancellation_estimator
[2025-03-12T12:39:07.680+0000] {connectionpool.py:868} WARNING - Retrying (Retry(total=5, connect=5, read=7, redirect=7, status=7)) after connection broken by 'NewConnectionError('<urllib3.connection.HTTPConnection object at 0xffff8659c200>: Failed to establish a new connection: [Errno 111] Connection refused')': /api/2.0/mlflow/experiments/get-by-name?experiment_name=cancellation_estimator
[2025-03-12T12:39:16.213+0000] {connectionpool.py:868} WARNING - Retrying (Retry(total=4, connect=4, read=7, redirect=7, status=7)) after connection broken by 'NewConnectionError('<urllib3.connection.HTTPConnection object at 0xffff8659c890>: Failed to establish a new connection: [Errno 111] Connection refused')': /api/2.0/mlflow/experiments/get-by-name?experiment_name=cancellation_estimator
[2025-03-12T12:39:32.914+0000] {connectionpool.py:868} WARNING - Retrying (Retry(total=3, connect=3, read=7, redirect=7, status=7)) after connection broken by 'NewConnectionError('<urllib3.connection.HTTPConnection object at 0xffff8659ce60>: Failed to establish a new connection: [Errno 111] Connection refused')': /api/2.0/mlflow/experiments/get-by-name?experiment_name=cancellation_estimator
[2025-03-12T12:40:05.861+0000] {connectionpool.py:868} WARNING - Retrying (Retry(total=2, connect=2, read=7, redirect=7, status=7)) after connection broken by 'NewConnectionError('<urllib3.connection.HTTPConnection object at 0xffff8659d400>: Failed to establish a new connection: [Errno 111] Connection refused')': /api/2.0/mlflow/experiments/get-by-name?experiment_name=cancellation_estimator
[2025-03-12T12:41:10.082+0000] {connectionpool.py:868} WARNING - Retrying (Retry(total=1, connect=1, read=7, redirect=7, status=7)) after connection broken by 'NewConnectionError('<urllib3.connection.HTTPConnection object at 0xffff8659d8e0>: Failed to establish a new connection: [Errno 111] Connection refused')': /api/2.0/mlflow/experiments/get-by-name?experiment_name=cancellation_estimator
[2025-03-13T14:08:58.940+0000] {local_task_job_runner.py:123} INFO - ::group::Pre task execution logs
[2025-03-13T14:08:58.950+0000] {taskinstance.py:2604} INFO - Dependencies not met for <TaskInstance: training-pipeline.training manual__2025-03-12T12:38:57.214725+00:00 [failed]>, dependency 'Task Instance State' FAILED: Task is in the 'failed' state.
[2025-03-13T14:08:58.951+0000] {local_task_job_runner.py:166} INFO - Task is not able to be run
