[2025-03-12T13:18:22.810+0000] {local_task_job_runner.py:123} INFO - ::group::Pre task execution logs
[2025-03-12T13:18:22.817+0000] {taskinstance.py:2614} INFO - Dependencies all met for dep_context=non-requeueable deps ti=<TaskInstance: training-pipeline.training manual__2025-03-12T13:18:14.448488+00:00 [queued]>
[2025-03-12T13:18:22.820+0000] {taskinstance.py:2614} INFO - Dependencies all met for dep_context=requeueable deps ti=<TaskInstance: training-pipeline.training manual__2025-03-12T13:18:14.448488+00:00 [queued]>
[2025-03-12T13:18:22.820+0000] {taskinstance.py:2867} INFO - Starting attempt 1 of 1
[2025-03-12T13:18:22.823+0000] {taskinstance.py:2890} INFO - Executing <Task(PythonOperator): training> on 2025-03-12 13:18:14.448488+00:00
[2025-03-12T13:18:22.827+0000] {warnings.py:112} WARNING - /home/***/.local/lib/python3.12/site-packages/***/task/task_runner/standard_task_runner.py:70: DeprecationWarning: This process (pid=106) is multi-threaded, use of fork() may lead to deadlocks in the child.
  pid = os.fork()

[2025-03-12T13:18:22.827+0000] {standard_task_runner.py:72} INFO - Started process 116 to run task
[2025-03-12T13:18:22.828+0000] {standard_task_runner.py:104} INFO - Running: ['***', 'tasks', 'run', 'training-pipeline', 'training', 'manual__2025-03-12T13:18:14.448488+00:00', '--job-id', '64', '--raw', '--subdir', 'DAGS_FOLDER/training_pipeline.py', '--cfg-path', '/tmp/tmpr_hvve5z']
[2025-03-12T13:18:22.829+0000] {standard_task_runner.py:105} INFO - Job 64: Subtask training
[2025-03-12T13:18:22.843+0000] {task_command.py:467} INFO - Running <TaskInstance: training-pipeline.training manual__2025-03-12T13:18:14.448488+00:00 [running]> on host ab1833a7b75c
[2025-03-12T13:18:22.867+0000] {taskinstance.py:3134} INFO - Exporting env vars: AIRFLOW_CTX_DAG_OWNER='user' AIRFLOW_CTX_DAG_ID='training-pipeline' AIRFLOW_CTX_TASK_ID='training' AIRFLOW_CTX_EXECUTION_DATE='2025-03-12T13:18:14.448488+00:00' AIRFLOW_CTX_TRY_NUMBER='1' AIRFLOW_CTX_DAG_RUN_ID='manual__2025-03-12T13:18:14.448488+00:00'
[2025-03-12T13:18:22.867+0000] {taskinstance.py:732} INFO - ::endgroup::
[2025-03-12T13:18:22.896+0000] {connectionpool.py:868} WARNING - Retrying (Retry(total=6, connect=6, read=7, redirect=7, status=7)) after connection broken by 'NewConnectionError('<urllib3.connection.HTTPConnection object at 0xffff4a9960c0>: Failed to establish a new connection: [Errno 111] Connection refused')': /api/2.0/mlflow/experiments/get-by-name?experiment_name=cancellation_estimator
[2025-03-12T13:18:27.433+0000] {connectionpool.py:868} WARNING - Retrying (Retry(total=5, connect=5, read=7, redirect=7, status=7)) after connection broken by 'NewConnectionError('<urllib3.connection.HTTPConnection object at 0xffff7eb94770>: Failed to establish a new connection: [Errno 111] Connection refused')': /api/2.0/mlflow/experiments/get-by-name?experiment_name=cancellation_estimator
[2025-03-12T13:18:35.806+0000] {connectionpool.py:868} WARNING - Retrying (Retry(total=4, connect=4, read=7, redirect=7, status=7)) after connection broken by 'NewConnectionError('<urllib3.connection.HTTPConnection object at 0xffff7eb94b00>: Failed to establish a new connection: [Errno 111] Connection refused')': /api/2.0/mlflow/experiments/get-by-name?experiment_name=cancellation_estimator
[2025-03-12T13:18:52.531+0000] {connectionpool.py:868} WARNING - Retrying (Retry(total=3, connect=3, read=7, redirect=7, status=7)) after connection broken by 'NewConnectionError('<urllib3.connection.HTTPConnection object at 0xffff7eb953d0>: Failed to establish a new connection: [Errno 111] Connection refused')': /api/2.0/mlflow/experiments/get-by-name?experiment_name=cancellation_estimator
[2025-03-12T13:19:25.045+0000] {connectionpool.py:868} WARNING - Retrying (Retry(total=2, connect=2, read=7, redirect=7, status=7)) after connection broken by 'NewConnectionError('<urllib3.connection.HTTPConnection object at 0xffff7eb95580>: Failed to establish a new connection: [Errno 111] Connection refused')': /api/2.0/mlflow/experiments/get-by-name?experiment_name=cancellation_estimator
[2025-03-12T13:20:29.787+0000] {connectionpool.py:868} WARNING - Retrying (Retry(total=1, connect=1, read=7, redirect=7, status=7)) after connection broken by 'NewConnectionError('<urllib3.connection.HTTPConnection object at 0xffff7eb95bb0>: Failed to establish a new connection: [Errno 111] Connection refused')': /api/2.0/mlflow/experiments/get-by-name?experiment_name=cancellation_estimator
[2025-03-13T14:08:58.942+0000] {local_task_job_runner.py:123} INFO - ::group::Pre task execution logs
[2025-03-13T14:08:58.953+0000] {taskinstance.py:2604} INFO - Dependencies not met for <TaskInstance: training-pipeline.training manual__2025-03-12T13:18:14.448488+00:00 [failed]>, dependency 'Task Instance State' FAILED: Task is in the 'failed' state.
[2025-03-13T14:08:58.954+0000] {local_task_job_runner.py:166} INFO - Task is not able to be run
