[2025-03-15T05:19:51.672+0000] {local_task_job_runner.py:123} INFO - ::group::Pre task execution logs
[2025-03-15T05:19:51.690+0000] {taskinstance.py:2614} INFO - Dependencies all met for dep_context=non-requeueable deps ti=<TaskInstance: training-pipeline.validation manual__2025-03-15T05:19:35.192260+00:00 [queued]>
[2025-03-15T05:19:51.695+0000] {taskinstance.py:2614} INFO - Dependencies all met for dep_context=requeueable deps ti=<TaskInstance: training-pipeline.validation manual__2025-03-15T05:19:35.192260+00:00 [queued]>
[2025-03-15T05:19:51.695+0000] {taskinstance.py:2867} INFO - Starting attempt 1 of 1
[2025-03-15T05:19:51.793+0000] {taskinstance.py:2890} INFO - Executing <Task(PythonOperator): validation> on 2025-03-15 05:19:35.192260+00:00
[2025-03-15T05:19:51.797+0000] {warnings.py:112} WARNING - /home/***/.local/lib/python3.12/site-packages/***/task/task_runner/standard_task_runner.py:70: DeprecationWarning: This process (pid=163) is multi-threaded, use of fork() may lead to deadlocks in the child.
  pid = os.fork()

[2025-03-15T05:19:51.797+0000] {standard_task_runner.py:72} INFO - Started process 173 to run task
[2025-03-15T05:19:51.798+0000] {standard_task_runner.py:104} INFO - Running: ['***', 'tasks', 'run', 'training-pipeline', 'validation', 'manual__2025-03-15T05:19:35.192260+00:00', '--job-id', '65', '--raw', '--subdir', 'DAGS_FOLDER/training_pipeline.py', '--cfg-path', '/tmp/tmprlyt3is_']
[2025-03-15T05:19:51.798+0000] {standard_task_runner.py:105} INFO - Job 65: Subtask validation
[2025-03-15T05:19:51.817+0000] {task_command.py:467} INFO - Running <TaskInstance: training-pipeline.validation manual__2025-03-15T05:19:35.192260+00:00 [running]> on host c5434a130e61
[2025-03-15T05:19:51.849+0000] {taskinstance.py:3134} INFO - Exporting env vars: AIRFLOW_CTX_DAG_OWNER='user' AIRFLOW_CTX_DAG_ID='training-pipeline' AIRFLOW_CTX_TASK_ID='validation' AIRFLOW_CTX_EXECUTION_DATE='2025-03-15T05:19:35.192260+00:00' AIRFLOW_CTX_TRY_NUMBER='1' AIRFLOW_CTX_DAG_RUN_ID='manual__2025-03-15T05:19:35.192260+00:00'
[2025-03-15T05:19:51.850+0000] {taskinstance.py:732} INFO - ::endgroup::
[2025-03-15T05:19:51.857+0000] {condition_step.py:45} INFO - Run_id: 758a6f3e4e7648ac84587367c40096ac
[2025-03-15T05:19:51.910+0000] {logging_mixin.py:190} WARNING - Registered model 'cancellation_estimator' already exists. Creating a new version of this model...
[2025-03-15T05:19:51.929+0000] {logging_mixin.py:190} WARNING - 2025/03/15 05:19:51 INFO mlflow.store.model_registry.abstract_store: Waiting up to 300 seconds for model version to finish creation. Model name: cancellation_estimator, version 3
[2025-03-15T05:19:51.929+0000] {logging_mixin.py:190} WARNING - Created version '3' of model 'cancellation_estimator'.
[2025-03-15T05:19:51.929+0000] {condition_step.py:60} INFO - New model registered.
[2025-03-15T05:19:51.929+0000] {taskinstance.py:3313} ERROR - Task failed with exception
Traceback (most recent call last):
  File "/home/airflow/.local/lib/python3.12/site-packages/airflow/models/taskinstance.py", line 768, in _execute_task
    result = _execute_callable(context=context, **execute_callable_kwargs)
             ^^^^^^^^^^^^^^^^^^^^^^^^^^^^^^^^^^^^^^^^^^^^^^^^^^^^^^^^^^^^^
  File "/home/airflow/.local/lib/python3.12/site-packages/airflow/models/taskinstance.py", line 734, in _execute_callable
    return ExecutionCallableRunner(
           ^^^^^^^^^^^^^^^^^^^^^^^^
  File "/home/airflow/.local/lib/python3.12/site-packages/airflow/utils/operator_helpers.py", line 252, in run
    return self.func(*args, **kwargs)
           ^^^^^^^^^^^^^^^^^^^^^^^^^^
  File "/home/airflow/.local/lib/python3.12/site-packages/airflow/models/baseoperator.py", line 424, in wrapper
    return func(self, *args, **kwargs)
           ^^^^^^^^^^^^^^^^^^^^^^^^^^^
  File "/home/airflow/.local/lib/python3.12/site-packages/airflow/operators/python.py", line 238, in execute
    return_value = self.execute_callable()
                   ^^^^^^^^^^^^^^^^^^^^^^^
  File "/home/airflow/.local/lib/python3.12/site-packages/airflow/operators/python.py", line 256, in execute_callable
    return runner.run(*self.op_args, **self.op_kwargs)
           ^^^^^^^^^^^^^^^^^^^^^^^^^^^^^^^^^^^^^^^^^^^
  File "/home/airflow/.local/lib/python3.12/site-packages/airflow/utils/operator_helpers.py", line 252, in run
    return self.func(*args, **kwargs)
           ^^^^^^^^^^^^^^^^^^^^^^^^^^
  File "/opt/airflow/dags/steps/condition_step.py", line 62, in __call__
    latest_registered_model = registered_models[0]
                              ~~~~~~~~~~~~~~~~~^^^
IndexError: list index out of range
[2025-03-15T05:19:51.934+0000] {taskinstance.py:1226} INFO - Marking task as FAILED. dag_id=training-pipeline, task_id=validation, run_id=manual__2025-03-15T05:19:35.192260+00:00, execution_date=20250315T051935, start_date=20250315T051951, end_date=20250315T051951
[2025-03-15T05:19:51.946+0000] {taskinstance.py:341} INFO - ::group::Post task execution logs
[2025-03-15T05:19:51.946+0000] {standard_task_runner.py:124} ERROR - Failed to execute job 65 for task validation (list index out of range; 173)
Traceback (most recent call last):
  File "/home/airflow/.local/lib/python3.12/site-packages/airflow/task/task_runner/standard_task_runner.py", line 117, in _start_by_fork
    ret = args.func(args, dag=self.dag)
          ^^^^^^^^^^^^^^^^^^^^^^^^^^^^^
  File "/home/airflow/.local/lib/python3.12/site-packages/airflow/cli/cli_config.py", line 49, in command
    return func(*args, **kwargs)
           ^^^^^^^^^^^^^^^^^^^^^
  File "/home/airflow/.local/lib/python3.12/site-packages/airflow/utils/cli.py", line 116, in wrapper
    return f(*args, **kwargs)
           ^^^^^^^^^^^^^^^^^^
  File "/home/airflow/.local/lib/python3.12/site-packages/airflow/cli/commands/task_command.py", line 483, in task_run
    task_return_code = _run_task_by_selected_method(args, _dag, ti)
                       ^^^^^^^^^^^^^^^^^^^^^^^^^^^^^^^^^^^^^^^^^^^^
  File "/home/airflow/.local/lib/python3.12/site-packages/airflow/cli/commands/task_command.py", line 256, in _run_task_by_selected_method
    return _run_raw_task(args, ti)
           ^^^^^^^^^^^^^^^^^^^^^^^
  File "/home/airflow/.local/lib/python3.12/site-packages/airflow/cli/commands/task_command.py", line 341, in _run_raw_task
    return ti._run_raw_task(
           ^^^^^^^^^^^^^^^^^
  File "/home/airflow/.local/lib/python3.12/site-packages/airflow/utils/session.py", line 97, in wrapper
    return func(*args, session=session, **kwargs)
           ^^^^^^^^^^^^^^^^^^^^^^^^^^^^^^^^^^^^^^
  File "/home/airflow/.local/lib/python3.12/site-packages/airflow/models/taskinstance.py", line 3006, in _run_raw_task
    return _run_raw_task(
           ^^^^^^^^^^^^^^
  File "/home/airflow/.local/lib/python3.12/site-packages/airflow/models/taskinstance.py", line 274, in _run_raw_task
    TaskInstance._execute_task_with_callbacks(
  File "/home/airflow/.local/lib/python3.12/site-packages/airflow/models/taskinstance.py", line 3161, in _execute_task_with_callbacks
    result = self._execute_task(context, task_orig)
             ^^^^^^^^^^^^^^^^^^^^^^^^^^^^^^^^^^^^^^
  File "/home/airflow/.local/lib/python3.12/site-packages/airflow/models/taskinstance.py", line 3185, in _execute_task
    return _execute_task(self, context, task_orig)
           ^^^^^^^^^^^^^^^^^^^^^^^^^^^^^^^^^^^^^^^
  File "/home/airflow/.local/lib/python3.12/site-packages/airflow/models/taskinstance.py", line 768, in _execute_task
    result = _execute_callable(context=context, **execute_callable_kwargs)
             ^^^^^^^^^^^^^^^^^^^^^^^^^^^^^^^^^^^^^^^^^^^^^^^^^^^^^^^^^^^^^
  File "/home/airflow/.local/lib/python3.12/site-packages/airflow/models/taskinstance.py", line 734, in _execute_callable
    return ExecutionCallableRunner(
           ^^^^^^^^^^^^^^^^^^^^^^^^
  File "/home/airflow/.local/lib/python3.12/site-packages/airflow/utils/operator_helpers.py", line 252, in run
    return self.func(*args, **kwargs)
           ^^^^^^^^^^^^^^^^^^^^^^^^^^
  File "/home/airflow/.local/lib/python3.12/site-packages/airflow/models/baseoperator.py", line 424, in wrapper
    return func(self, *args, **kwargs)
           ^^^^^^^^^^^^^^^^^^^^^^^^^^^
  File "/home/airflow/.local/lib/python3.12/site-packages/airflow/operators/python.py", line 238, in execute
    return_value = self.execute_callable()
                   ^^^^^^^^^^^^^^^^^^^^^^^
  File "/home/airflow/.local/lib/python3.12/site-packages/airflow/operators/python.py", line 256, in execute_callable
    return runner.run(*self.op_args, **self.op_kwargs)
           ^^^^^^^^^^^^^^^^^^^^^^^^^^^^^^^^^^^^^^^^^^^
  File "/home/airflow/.local/lib/python3.12/site-packages/airflow/utils/operator_helpers.py", line 252, in run
    return self.func(*args, **kwargs)
           ^^^^^^^^^^^^^^^^^^^^^^^^^^
  File "/opt/airflow/dags/steps/condition_step.py", line 62, in __call__
    latest_registered_model = registered_models[0]
                              ~~~~~~~~~~~~~~~~~^^^
IndexError: list index out of range
[2025-03-15T05:19:51.978+0000] {local_task_job_runner.py:266} INFO - Task exited with return code 1
[2025-03-15T05:19:51.988+0000] {taskinstance.py:3901} INFO - 0 downstream tasks scheduled from follow-on schedule check
[2025-03-15T05:19:51.989+0000] {local_task_job_runner.py:245} INFO - ::endgroup::
